<?xml version = "1.0"?>
<robot name="cobot">
    
    <link name="base">

        <visual>
            <geometry>
                <cylinder radius="0.1" length="0.05"/>
            </geometry>
            <origin xyz = "0.0 0.0 0.025" rpy="0.0 0.0 0.0"/>
        </visual>
        <collision>
            <geometry>
                <cylinder radius="0.1" length="0.05"/>
            </geometry>
            <origin xyz = "0.0 0.0 0.025" rpy="0.0 0.0 0.0"/>
        </collision>

    </link>

    <joint name="base__link1" type="revolute">
        <parent link="base"/>
        <child link="link1"/>
        <axis xyz="0 0 1"/>
        <limit lower="-3.14159" upper="3.14159" velocity="0.5" effort="1000.0"/>
        <origin xyz="0 0 0.05" rpy="0 0 0"/>
    </joint>

    <link name="link1">
    
        <visual>
            <geometry>
                <cylinder radius="0.05" length="0.264"/>
            </geometry>
            <origin xyz = "0.0 0.0 0.132" rpy="0.0 0.0 0.0"/>
        </visual>
        <collision>
            <geometry>
                <cylinder radius="0.05" length="0.264"/>
            </geometry>
            <origin xyz = "0.0 0.0 0.132" rpy="0.0 0.0 0.0"/>
        </collision>

    </link>

</robot>